Workbook

Sheet EN articles
A1: ID_ENG | B1: Paper title | C1: Authors | D1: Year | E1: Journal/Conference | F1: Citations | G1: First author | H1: First author affiliation | I1: Author Keywords | J1: MGT/Tech/ENG | K1: Paper type | L1: Methodology | M1: Focus | N1: Application Domain | O1: Use case | P1: industrial sector | Q1: Theory lens | R1: GenAI Technology Type | S1: Key findings | T1: Reported Impacts of GenAI | U1: Enablers / Success Factors | V1: Barriers / Challenges | W1: GenAI role | X1: Tech details | Y1: Comment | Z1: Relevance Rating (1–5) | AA1: Quality Rating (1–5) | AB1: Technology readiness | AC1: Technology readiness - sub level | AD1: GenAI autonomy | AE1: ChatGPT 5.1 Thinking agreement? | AF1: Discrepency | AG1: ChatGPT explanation for Technology readiness (explain) | AH1: ChatGPT explanation for GenAI autonomy (explain) | AI1: My argument | AK1: TRL axis | AL1: GenAI autonomy level
A2: 1 | B2: CausalKGPT: Industrial structure causal knowledge-enhanced large language model for cause analysis of quality problems in aerospace product manufacturing | C2: Zhou B.; Li X.; Liu T.; Xu K.; Liu W.; Bao J. | D2: 2024 | E2: Advanced Engineering Informatics | F2: 61 | G2: =IFERROR(LEFT(C2, FIND(";", C2) - 1), C2) -> Zhou B. | H2: School of Artificial Intelligence, Anhui Polytechnic University, Wuhu, 241000, China | I2: Aerospace product; Causal knowledge graph-guided prompt; Causal quality-related knowledge graph; Cause analysis of quality defects; Large language model | J2: =IF(OR( E2="International Journal of Production Research", E2="Journal of Manufacturing Technology Management", E2="International Journal of Production Economics", E2="Journal of Industrial Information Integration", E2="Transportation Research Part E: Logistics and Transportation Review", E2="Journal of Cleaner Production", E2="MM 2024 - Proceedings of the 32nd ACM International Conference on Multimedia", E2="Oeconomia Copernicana", E2="Technology in Society" ), "MGT", "ENG") -> ENG | K2: empirical | L2: Design science research | M2: Techniques; Applications | N2: Manufacturing | O2: fault diagnosis | P2: Aerospace | R2: KG‑augmented LLM | S2: scgSPN reinforces casual links;CQkg+Ptuned chatglm CausalKgpt beat base+near gpt4 on aerospace qual Q&A | T2: more expert;relaible answers;seclevel responce;enhanced casual robustness for defect diag | U2: highqual CQkg;expert curatd documents | V2: confidental data limits benchmrks;single confounder;need fine grain data;retrianing for reliabilty/safe | X2: scgSPN network modle extracts casual relations from qual docs to build CQkg casual kg;producing CausalKgpt for defect diag | Y2: a KG-enabled fine-tuned LLM on quality issues Q&A in aerospace; data is confidential | Z2: 4 | AA2: 4 | AB2: Lab validation | AC2: Core function validation | AD2: Assistive GenAI | AE2: Y | AG2: Feasibility is shown via comparative experiments in a lab HRC cell (HoloLens2, UR5e+MiR100); results demonstrate performance but not a field pilot/production rollout | AH2: The paper frames CausalKGPT as a tool to assist workers in cause analyses and recommendations and emphasizes an offline model, not one that executes or controls processes. humans remain the decision/actuation gate | AK2: {=_xlfn.IFS(AC2="Principles observation",1, AC2="Concept formulation",2, AC2="Proof-of-concept simulation", 3, AC2="Core function validation", 4, AC2="Integration component testing", 5, AC2="Component validation in relevant environment", 6, AC2="Subsystem demonstration in relevant environment", 7, AC2="System demonstration in operational environment", 8, AC2="Production qualification", 9, AC2="Mission-proven operations", 10)} -> 4 | AL2: {=_xlfn.IFS(AD2="Assistive GenAI", 1, AD2="GenAI-led with human oversight", 2, AD2="Autonomous process learning", 3)} -> 1
A3: 2 | B3: Leveraging error-assisted fine-tuning large language models for manufacturing excellence | C3: Xia L.; Li C.; Zhang C.; Liu S.; Zheng P. | D3: 2024 | E3: Robotics and Computer-Integrated Manufacturing | F3: 45 | G3: =IFERROR(LEFT(C3, FIND(";", C3) - 1), C3) -> Xia L. | H3: Department of Industrial and Systems Engineering, The Hong Kong Polytechnic University, Hong Kong | I3: Generative AI; Industry 4.0; Knowledge management; Large language model; Smart manufacturing | J3: =IF(OR( E3="International Journal of Production Research", E3="Journal of Manufacturing Technology Management", E3="International Journal of Production Economics", E3="Journal of Industrial Information Integration", E3="Transportation Research Part E: Logistics and Transportation Review", E3="Journal of Cleaner Production", E3="MM 2024 - Proceedings of the 32nd ACM International Conference on Multimedia", E3="Oeconomia Copernicana", E3="Technology in Society" ), "MGT", "ENG") -> ENG | K3: empirical | L3: Design science research | M3: Techniques; Applications | N3: Manufacturing | O3: human–robot collaboration | R3: LLM chatbot | S3: mfgtuned llm improve judgment acc~4.1%+gen vaild domian code w/closed loop refinement | T3: better domian answers;more relaible code;eff gains;broader aplicability to mfg tasks | V3: uncertainity;reliabilty;effectiveness;lack domian knowlege | W3: Execute — Translates natural-language tasks and scene context into executable robot code with safety checks and guardrails | X3: errorassisted fine tunning llm w/mfg data;based on openais gpt davinci modle in Python platform | Y3: fine-tuned LLM on robot code generation and more | Z3: 4 | AA3: 4 | AB3: Lab validation | AC3: Core function validation | AD3: Assistive GenAI | AE3: Y | AG3: Proposes and tests a fine-tuning plus error-assisted code generation framework on curated manufacturing corpora and benchmark tasks; code is generated and verified in controlled experiments, not integrated with real shop-floor systems. | AH3: LLM answers manufacturing queries and generates domain-specific code that engineers review, adapt, and deploy; GenAI expands human capability but never directly operates machinery or autonomously executes manufacturing processes. | AK3: {=_xlfn.IFS(AC3="Principles observation",1, AC3="Concept formulation",2, AC3="Proof-of-concept simulation", 3, AC3="Core function validation", 4, AC3="Integration component testing", 5, AC3="Component validation in relevant environment", 6, AC3="Subsystem demonstration in relevant environment", 7, AC3="System demonstration in operational environment", 8, AC3="Production qualification", 9, AC3="Mission-proven operations", 10)} -> 4 | AL3: {=_xlfn.IFS(AD3="Assistive GenAI", 1, AD3="GenAI-led with human oversight", 2, AD3="Autonomous process learning", 3)} -> 1
A4: 3 | B4: From natural language to simulations: applying AI to automate simulation modelling of logistics systems | C4: Jackson I.; Jesus Saenz M.; Ivanov D. | D4: 2024 | E4: International Journal of Production Research | F4: 44 | G4: =IFERROR(LEFT(C4, FIND(";", C4) - 1), C4) -> Jackson I. | H4: Center for Transportation & Logistics, Massachusetts Institute of Technology, Cambridge, MA, United States | I4: artificial intelligence; Generative AI; GPT-3; NLP; simulation; supply chain | J4: ENG | K4: empirical | L4: Design science research | M4: Applications | N4: Supply Chain | O4: modelling of queuing & inventory control | Q4: human-AI collaboration principles | R4: LLM chatbot | S4: codex gen functionaly vaild inventory/queuing simulations from verbal descrips | T4: eff gains | U4: capability of genai;human expert vaild | V4: initial investment;continous updates w/data;scale up;contextulisation of ai | X4: using gpt3 codex davincicodex engine to gen simulaiton modles for inventory+queuing sys | Y4: directly using Codex for code completion for logistics modelling | Z4: 4 | AA4: 4 | AB4: Concept | AC4: Proof-of-concept simulation | AD4: Assistive GenAI | AE4: Y | AG4: GPT-3/Codex is used to automatically generate simulation models from verbal descriptions and validated on queuing and inventory examples entirely in simulation, without connection to real logistics assets or live enterprise data. | AH4: GenAI supports analysts by turning natural language into simulation code; humans still specify problems, inspect generated models, run experiments, and interpret results, so the AI acts as a modelling copilot rather than process controller. | AK4: {=_xlfn.IFS(AC4="Principles observation",1, AC4="Concept formulation",2, AC4="Proof-of-concept simulation", 3, AC4="Core function validation", 4, AC4="Integration component testing", 5, AC4="Component validation in relevant environment", 6, AC4="Subsystem demonstration in relevant environment", 7, AC4="System demonstration in operational environment", 8, AC4="Production qualification", 9, AC4="Mission-proven operations", 10)} -> 3 | AL4: {=_xlfn.IFS(AD4="Assistive GenAI", 1, AD4="GenAI-led with human oversight", 2, AD4="Autonomous process learning", 3)} -> 1
A5: 4 | B5: An LLM-based approach for enabling seamless Human-Robot collaboration in assembly | C5: Gkournelos C.; Konstantinou C.; Makris S., (2) | D5: 2024 | E5: CIRP Annals | F5: 35 | G5: =IFERROR(LEFT(C5, FIND(";", C5) - 1), C5) -> Gkournelos C. | H5: Laboratory for Manufacturing Systems and Automation, Department of Mechanical Engineering and Aeronautics, University of Patras, Patras, Greece | I5: Human robot collaboration; Large language models; Manufacturing systems | J5: =IF(OR( E5="International Journal of Production Research", E5="Journal of Manufacturing Technology Management", E5="International Journal of Production Economics", E5="Journal of Industrial Information Integration", E5="Transportation Research Part E: Logistics and Transportation Review", E5="Journal of Cleaner Production", E5="MM 2024 - Proceedings of the 32nd ACM International Conference on Multimedia", E5="Oeconomia Copernicana", E5="Technology in Society" ), "MGT", "ENG") -> ENG | K5: empirical | L5: Design science research | M5: Applications | N5: Manufacturing | O5: human–robot collaboration; assembly | P5: automotive & machinery | R5: LLM chatbot | S5: llm enabled chatbot rag+CoT prompt engineering based on gpt3.5+gpt4 yields excutable HRC schedules | T5: faster config;improved collabration/eff | X5: rag+CoT prompt engineering based on gpt3.5+gpt4 for 2 assembly tasks in automotive & machinery | Y5: not in-depth tech paper | Z5: 4 | AA5: 2 | AB5: Lab validation | AC5: Integration component testing | AD5: GenAI-led with human oversight | AE5: Y | AG5: Implements an LLM-based execution system integrated with digital twin, knowledge bases, UR10 cobot and AR interface, validated on two assembly testbeds; full stack is exercised, but only in controlled lab-style HRC cells. | AH5: HRC-GPT interprets natural-language requests, generates assembly schedules, allocates tasks and interacts with robot controllers, while operators supervise via AR, can reconfigure and intervene, keeping humans “on the loop” during execution. | AK5: {=_xlfn.IFS(AC5="Principles observation",1, AC5="Concept formulation",2, AC5="Proof-of-concept simulation", 3, AC5="Core function validation", 4, AC5="Integration component testing", 5, AC5="Component validation in relevant environment", 6, AC5="Subsystem demonstration in relevant environment", 7, AC5="System demonstration in operational environment", 8, AC5="Production qualification", 9, AC5="Mission-proven operations", 10)} -> 5 | AL5: {=_xlfn.IFS(AD5="Assistive GenAI", 1, AD5="GenAI-led with human oversight", 2, AD5="Autonomous process learning", 3)} -> 2
A6: 5 | B6: An LLM-based vision and language cobot navigation approach for Human-centric Smart Manufacturing | C6: Wang T.; Fan J.; Zheng P. | D6: 2024 | E6: Journal of Manufacturing Systems | F6: 29 | G6: =IFERROR(LEFT(C6, FIND(";", C6) - 1), C6) -> Wang T. | H6: Department of Industrial and Systems Engineering, The Hong Kong Polytechnic University, Hong Kong | I6: Human-centric smart manufacturing; Large language model; Vision and language navigation | J6: =IF(OR( E6="International Journal of Production Research", E6="Journal of Manufacturing Technology Management", E6="International Journal of Production Economics", E6="Journal of Industrial Information Integration", E6="Transportation Research Part E: Logistics and Transportation Review", E6="Journal of Cleaner Production", E6="MM 2024 - Proceedings of the 32nd ACM International Conference on Multimedia", E6="Oeconomia Copernicana", E6="Technology in Society" ), "MGT", "ENG") -> ENG | K6: empirical | L6: Design science research | M6: Applications | N6: Manufacturing | O6: human–robot collaboration | R6: LLM chatbot | S6: embed llm into Automated Guided Vehicle AGV to comprehend NL commands+gen Python code to;AGV accurately follows complex instructions of toolfetching in humancentric mfg | W6: Execute — Translates natural-language tasks and scene context into executable robot code with safety checks and guardrails | X6: gpt3.5turbo modle from openai employed to convert dialogue+instructions into excutable Python code for impl | Y6: The generated Python code is then executed using the "exec" function in Python to enable the robot to move according to the user's navigation instructions | Z6: 4 | AA6: 3 | AB6: Concept | AC6: Proof-of-concept simulation | AD6: GenAI-led with human oversight | AE6: Y | AG6: Navigation framework is implemented in AI Habitat; a simulated AGV in a reconstructed 3D HRC scene follows language-driven paths. All evaluations occur in simulation, without deployment on physical AGVs or factory IT/OT. | AH6: The LLM interprets human language commands and autonomously generates Python navigation code and paths for the AGV; humans issue goals and could supervise or stop runs, but do not micromanage movement-level actions. | AK6: {=_xlfn.IFS(AC6="Principles observation",1, AC6="Concept formulation",2, AC6="Proof-of-concept simulation", 3, AC6="Core function validation", 4, AC6="Integration component testing", 5, AC6="Component validation in relevant environment", 6, AC6="Subsystem demonstration in relevant environment", 7, AC6="System demonstration in operational environment", 8, AC6="Production qualification", 9, AC6="Mission-proven operations", 10)} -> 3 | AL6: {=_xlfn.IFS(AD6="Assistive GenAI", 1, AD6="GenAI-led with human oversight", 2, AD6="Autonomous process learning", 3)} -> 2
A7: 6 | B7: Empowering digital twins with large language models for global temporal feature learning | C7: Sun Y.; Zhang Q.; Bao J.; Lu Y.; Liu S. | D7: 2024 | E7: Journal of Manufacturing Systems | F7: 26 | G7: =IFERROR(LEFT(C7, FIND(";", C7) - 1), C7) -> Sun Y. | H7: College of Mechanical Engineering, Donghua University, Shanghai, 201620, China | I7: Digital Twin; Large Language Model (LLM); Multi-Agent Systems (MAS) | J7: =IF(OR( E7="International Journal of Production Research", E7="Journal of Manufacturing Technology Management", E7="International Journal of Production Economics", E7="Journal of Industrial Information Integration", E7="Transportation Research Part E: Logistics and Transportation Review", E7="Journal of Cleaner Production", E7="MM 2024 - Proceedings of the 32nd ACM International Conference on Multimedia", E7="Oeconomia Copernicana", E7="Technology in Society" ), "MGT", "ENG") -> ENG | K7: empirical | N7: Operations | O7: fault diagnosis; maintenance | R7: LLM enabled digital twin | S7: genai agents semanticize logs;retrieve cases,+deliberate to recommend causes/prognoses;beat base llms in bridgecrane evaluation | X7: in dt;llm Vicuna13B acts as explainable reasoning engine;recalls similar faults;debates alternatives,+recommends/justifies likely cause+next steps | Y7: low quality paper | Z7: 3 | AA7: 3 | AB7: Concept | AC7: Proof-of-concept simulation | AD7: Assistive GenAI | AE7: Y | AG7: Multi-agent LLM digital twin is evaluated offline on historical crane sensor sequences and fault investigation documents via ablation studies; no real-time coupling or automatic maintenance actions in the actual plant. | AH7: A multi-agent, LLM-driven DT coordinates agents to produce diagnoses/decisions with traceable reasoning; users can intervene, but the system aggregates and fuses insights across agents | AK7: {=_xlfn.IFS(AC7="Principles observation",1, AC7="Concept formulation",2, AC7="Proof-of-concept simulation", 3, AC7="Core function validation", 4, AC7="Integration component testing", 5, AC7="Component validation in relevant environment", 6, AC7="Subsystem demonstration in relevant environment", 7, AC7="System demonstration in operational environment", 8, AC7="Production qualification", 9, AC7="Mission-proven operations", 10)} -> 3 | AL7: {=_xlfn.IFS(AD7="Assistive GenAI", 1, AD7="GenAI-led with human oversight", 2, AD7="Autonomous process learning", 3)} -> 1
A8: 7 | B8: A vision-language-guided and deep reinforcement learning-enabled approach for unstructured human-robot collaborative manufacturing task fulfilment | C8: Zheng P.; Li C.; Fan J.; Wang L. | D8: 2024 | E8: CIRP Annals | F8: 16 | G8: =IFERROR(LEFT(C8, FIND(";", C8) - 1), C8) -> Zheng P. | H8: Department of Industrial and Systems Engineering, The Hong Kong Polytechnic University, Hong Kong | I8: Human-guided robot learning; Human-robot collaboration; Manufacturing system | J8: =IF(OR( E8="International Journal of Production Research", E8="Journal of Manufacturing Technology Management", E8="International Journal of Production Economics", E8="Journal of Industrial Information Integration", E8="Transportation Research Part E: Logistics and Transportation Review", E8="Journal of Cleaner Production", E8="MM 2024 - Proceedings of the 32nd ACM International Conference on Multimedia", E8="Oeconomia Copernicana", E8="Technology in Society" ), "MGT", "ENG") -> ENG | K8: empirical | L8: Design science research | M8: Techniques; Applications | N8: Manufacturing | O8: human–robot collaboration | R8: LLM chatbot | S8: llmbased zeroshot robotic task plan generation;Its feasibility demonstrated in several HRC unstructured mfg tasks | T8: llms for adaptive task planing+Python robot code generation | W8: Execute — Translates natural-language tasks and scene context into executable robot code with safety checks and guardrails | X8: gpt3.5 for robotic task plan generation+codex robot code generation | Y8: another HRC work: commercial LLMs for adaptive task planning and Python robot code generation | Z8: 4 | AA8: 3 | AB8: Lab validation | AC8: Integration component testing | AD8: GenAI-led with human oversight | AE8: Y | AG8: Vision-language planner and DRL controller are implemented on a UR5e+MiR100 mobile manipulator with Kinect and HoloLens in a lab HRC cell; integrated components tested, not deployed on production lines. | AH8: Vision-language + LLM plan tasks and hand off to a DRL controller to execute primitives; human guidance remains central via MR-HMD, so it coordinates modules rather than acting fully autonomously | AK8: {=_xlfn.IFS(AC8="Principles observation",1, AC8="Concept formulation",2, AC8="Proof-of-concept simulation", 3, AC8="Core function validation", 4, AC8="Integration component testing", 5, AC8="Component validation in relevant environment", 6, AC8="Subsystem demonstration in relevant environment", 7, AC8="System demonstration in operational environment", 8, AC8="Production qualification", 9, AC8="Mission-proven operations", 10)} -> 5 | AL8: {=_xlfn.IFS(AD8="Assistive GenAI", 1, AD8="GenAI-led with human oversight", 2, AD8="Autonomous process learning", 3)} -> 2
A9: 8 | B9: Building a knowledge graph to enrich ChatGPT responses in manufacturing service discovery | C9: Li Y.; Starly B. | D9: 2024 | E9: Journal of Industrial Information Integration | F9: 14 | G9: =IFERROR(LEFT(C9, FIND(";", C9) - 1), C9) -> Li Y. | H9: Edward P. Fitts Department of Industrial & Systems Engineering, North Carolina State University, United States | I9: ChatGPT; Digital supply chain; Knowledge graph; Manufacturing service discovery | J9: ENG | K9: empirical | L9: Design science research | M9: Applications | N9: Supply Chain | O9: supplier identification | R9: KG‑augmented LLM | S9: kg+chatgpt beat gpt4 on complex sourcing | T9: more relaible;interpretable QA;efficent manufacturer discovery;supports diversification/resilience | V9: noisy/outdated websites;crossdomian integr;improve llm understanding of kgs | W9: Align — Retrieves and normalizes manufacturer knowledge, translating questions into structured graph queries and answers with provenance. | X9: constructs 13240entity mfg Service kg from websites+Wikidata;Neo4j+LangChain translate NL→Cypher;Node2Vec/GraphSAGE embeddings;chatgpt+kg QA surpasses gpt4 on complex sourcing queries in experiments | Y9: KG+ChatGPT for supplier identification | Z9: 5 | AA9: 4 | AB9: Lab validation | AC9: Core function validation | AD9: Assistive GenAI | AE9: Y | AG9: ChatGPT is integrated with a Neo4j manufacturing knowledge graph built from real company data; evaluation uses offline benchmark questions, with no integration into live procurement workflows or operational IT/OT systems | AH9: System enriches conversational answers about potential manufacturing service providers; it suggests candidates and rationales, but humans still choose suppliers and act, so GenAI only assists information retrieval and decision framing | AK9: {=_xlfn.IFS(AC9="Principles observation",1, AC9="Concept formulation",2, AC9="Proof-of-concept simulation", 3, AC9="Core function validation", 4, AC9="Integration component testing", 5, AC9="Component validation in relevant environment", 6, AC9="Subsystem demonstration in relevant environment", 7, AC9="System demonstration in operational environment", 8, AC9="Production qualification", 9, AC9="Mission-proven operations", 10)} -> 4 | AL9: {=_xlfn.IFS(AD9="Assistive GenAI", 1, AD9="GenAI-led with human oversight", 2, AD9="Autonomous process learning", 3)} -> 1
A10: 9 | B10: A vision-language-guided robotic action planning approach for ambiguity mitigation in human–robot collaborative manufacturing | C10: Fan J.; Zheng P. | D10: 2024 | E10: Journal of Manufacturing Systems | F10: 12 | G10: =IFERROR(LEFT(C10, FIND(";", C10) - 1), C10) -> Fan J. | H10: Department of Industrial and Systems Engineering, The Hong Kong Polytechnic University, Hong Kong | I10: Computer vision; Deep learning; Human–robot collaboration; Smart manufacturing; Vision-language reasoning | J10: =IF(OR( E10="International Journal of Production Research", E10="Journal of Manufacturing Technology Management", E10="International Journal of Production Economics", E10="Journal of Industrial Information Integration", E10="Transportation Research Part E: Logistics and Transportation Review", E10="Journal of Cleaner Production", E10="MM 2024 - Proceedings of the 32nd ACM International Conference on Multimedia", E10="Oeconomia Copernicana", E10="Technology in Society" ), "MGT", "ENG") -> ENG | K10: empirical | L10: Design science research | M10: Techniques; Applications | N10: Manufacturing | O10: human–robot collaboration | R10: LLM chatbot | S10: llm gpt4 robotic planing, 93.3% success | V10: occasional hallucinations | W10: Execute — Translates natural-language tasks and scene context into executable robot code with safety checks and guardrails | X10: llm task planner gpt4/3.5;llama2 generating excutable robot code | Y10: another HRC work: commercial LLMs for adaptive task planning and Python robot code generation | Z10: 4 | AA10: 3 | AB10: Lab validation | AC10: Integration component testing | AD10: GenAI-led with human oversight | AE10: Y | AG10: Referred object retrieval and LLM-based planner are validated on lab HRC gear-pump assembly with UR5 and Kinect plus evaluations on RefCOCO; integrated perception–planning stack tested, not connected to production MES. | AH10: LLM generates executable robot code from language and vision, calling primitive skills to perform pick-and-place; humans provide initial commands and occasional clicks, supervising outcomes but not approving every motion beforehand. | AK10: {=_xlfn.IFS(AC10="Principles observation",1, AC10="Concept formulation",2, AC10="Proof-of-concept simulation", 3, AC10="Core function validation", 4, AC10="Integration component testing", 5, AC10="Component validation in relevant environment", 6, AC10="Subsystem demonstration in relevant environment", 7, AC10="System demonstration in operational environment", 8, AC10="Production qualification", 9, AC10="Mission-proven operations", 10)} -> 5 | AL10: {=_xlfn.IFS(AD10="Assistive GenAI", 1, AD10="GenAI-led with human oversight", 2, AD10="Autonomous process learning", 3)} -> 2
A11: 11 | B11: Generative AI and DT integrated intelligent process planning: a conceptual framework | C11: Xu Q.; Zhou G.; Zhang C.; Chang F.; Cao Y.; Zhao D. | D11: 2024 | E11: International Journal of Advanced Manufacturing Technology | F11: 10 | G11: =IFERROR(LEFT(C11, FIND(";", C11) - 1), C11) -> Xu Q. | H11: School of Mechanical Engineering, Xi’an Jiaotong University, No.28 Xianning West Road, Xi’an, 710049, China | I11: CAPP; DT; Generative AI; Intelligent process planning; Transformer | J11: =IF(OR( E11="International Journal of Production Research", E11="Journal of Manufacturing Technology Management", E11="International Journal of Production Economics", E11="Journal of Industrial Information Integration", E11="Transportation Research Part E: Logistics and Transportation Review", E11="Journal of Cleaner Production", E11="MM 2024 - Proceedings of the 32nd ACM International Conference on Multimedia", E11="Oeconomia Copernicana", E11="Technology in Society" ), "MGT", "ENG") -> ENG | K11: empirical | L11: Design science research | M11: Techniques; Applications | N11: Manufacturing | O11: process planning | R11: LLM enabled digital twin | S11: propose GIPP:Processgpt+dt verfication;finetunes gpt3 on 2458 Q&A;milling prototype show flexibel;veriifiable planing vs CAPP | T11: greater adaptability;userfriendliness;reliabilty;explainability | V11: narrow milling dataset;unimodal gpt3 | W11: Reason — Plans milling processes from textual know-how and revises steps using digital-twin verification feedback for reliability. | X11: fine tunw gpt3 davinci002 Processgpt;it then answers proc questions+drafts proc plans steps;tools;parameters in structured proc card format> Hands plans to dt>dt results loop back to llm for | Y11: proposes conceptual framework-->verify with a prototype. lacking extensive quantitative evaluation | Z11: 4 | AA11: 3 | AB11: Lab validation | AC11: Integration component testing | AD11: GenAI-led with human oversight | AE11: Y | AG11: Prototype GIPP platform couples a fine-tuned ProcessGPT, CAM and a DT of a three-axis CNC milling machine, executing milling of a thin-walled part in an experimental cell, not in full production. | AH11: ProcessGPT automatically proposes complete process plans and drives NC code generation via CAM and DT verification, while engineers supply requirements, review outputs, and supervise machining execution, keeping humans on the loop. | AK11: {=_xlfn.IFS(AC11="Principles observation",1, AC11="Concept formulation",2, AC11="Proof-of-concept simulation", 3, AC11="Core function validation", 4, AC11="Integration component testing", 5, AC11="Component validation in relevant environment", 6, AC11="Subsystem demonstration in relevant environment", 7, AC11="System demonstration in operational environment", 8, AC11="Production qualification", 9, AC11="Mission-proven operations", 10)} -> 5 | AL11: {=_xlfn.IFS(AD11="Assistive GenAI", 1, AD11="GenAI-led with human oversight", 2, AD11="Autonomous process learning", 3)} -> 2
A12: 12 | B12: Assessment of a large language model based digital intelligent assistant in assembly manufacturing | C12: Colabianchi S.; Costantino F.; Sabetta N. | D12: 2024 | E12: Computers in Industry | F12: 10 | G12: =IFERROR(LEFT(C12, FIND(";", C12) - 1), C12) -> Colabianchi S. | H12: Department of computer, control, and management engineering Antonio Ruberti, Sapienza University of Rome, Via Ariosto 25, Rome, 00185, Italy | I12: Artificial intelligence; Chatbot; Experimental design; Industry 4.0; Industry 5.0; Natural language processing | J12: =IF(OR( E12="International Journal of Production Research", E12="Journal of Manufacturing Technology Management", E12="International Journal of Production Economics", E12="Journal of Industrial Information Integration", E12="Transportation Research Part E: Logistics and Transportation Review", E12="Journal of Cleaner Production", E12="MM 2024 - Proceedings of the 32nd ACM International Conference on Multimedia", E12="Oeconomia Copernicana", E12="Technology in Society" ), "MGT", "ENG") -> ENG | K12: empirical | L12: Lab experiment | M12: Applications; Value&Impact | N12: Manufacturing | O12: assembly | R12: LLM chatbot | S12: experimental voice llm assistant for assembly show high answer acc 93%;lower cognitive load+defects 3% hallucinations;strong usability | T12: reduced cognitive load;improved qual;high usability | X12: gpt4Turbo rag chatbot w/voice i/o | Y12: RAG chatbot dev & experiments like in SFS; BUT: participants are students, not workers; in lab instead of industrial context | Z12: 5 | AA12: 5 | AB12: Lab validation | AC12: Core function validation | AD12: Assistive GenAI | AE12: Y | AG12: ChatGPT-based digital intelligent assistant is implemented as a working prototype guiding workers in an assembly workstation with realistic tasks and curated instructions, evaluated experimentally in a controlled lab environment with student operators | AH12: The DIA only delivers instructions, answers questions and suggests actions through natural language; humans still perform all assembly steps, decide responses to issues, and physically operate tools and components. | AK12: {=_xlfn.IFS(AC12="Principles observation",1, AC12="Concept formulation",2, AC12="Proof-of-concept simulation", 3, AC12="Core function validation", 4, AC12="Integration component testing", 5, AC12="Component validation in relevant environment", 6, AC12="Subsystem demonstration in relevant environment", 7, AC12="System demonstration in operational environment", 8, AC12="Production qualification", 9, AC12="Mission-proven operations", 10)} -> 4 | AL12: {=_xlfn.IFS(AD12="Assistive GenAI", 1, AD12="GenAI-led with human oversight", 2, AD12="Autonomous process learning", 3)} -> 1
A13: 13 | B13: A novel approach to voice of customer extraction using GPT-3.5 Turbo: linking advanced NLP and Lean Six Sigma 4.0 | C13: Shahin M.; Chen F.F.; Hosseinzadeh A.; Maghanaki M.; Eghbalian A. | D13: 2024 | E13: International Journal of Advanced Manufacturing Technology | F13: 9 | G13: =IFERROR(LEFT(C13, FIND(";", C13) - 1), C13) -> Shahin M. | H13: Mechanical Engineering Department, The University of Texas at San Antonio, San Antonio, TX, United States | I13: ChatGPT; Industry 4.0; Large language model; Lean Six Sigma; Text mining and analysis; VoC | J13: =IF(OR( E13="International Journal of Production Research", E13="Journal of Manufacturing Technology Management", E13="International Journal of Production Economics", E13="Journal of Industrial Information Integration", E13="Transportation Research Part E: Logistics and Transportation Review", E13="Journal of Cleaner Production", E13="MM 2024 - Proceedings of the 32nd ACM International Conference on Multimedia", E13="Oeconomia Copernicana", E13="Technology in Society" ), "MGT", "ENG") -> ENG | K13: empirical | L13: Design science research | M13: Techniques; Applications | N13: Operations | O13: quality management | Q13: Lean Six Sigma | R13: LLM chatbot | S13: gpt3.5 processes suport dialogues to extract VoC;mapping to needs/requirements;show nuanced | T13: realtime customer insight;improved product/proc decisions;satisfaction;reduced churn | V13: slang/evolving language;historical bias;trend detection limits;ethics | X13: prompt gpt3.5Turbo to map comments→needs→requirements | Y13: simple usecase of chatgpt in extracting VoC, lacks quantitative evaluation | Z13: 4 | AA13: 3 | AB13: Lab validation | AC13: Core function validation | AD13: Assistive GenAI | AE13: Y | AG13: Researchers build a GPT-3.5-Turbo VoC pipeline processing thousands of Apple Support Twitter conversations, validating extraction quality on this real dataset without deploying the system into live customer service operations. | AH13: GPT-3.5-Turbo analyses historical dialogues and returns customer needs and requirements; Lean Six Sigma practitioners then interpret these insights to prioritize improvements, with no automated changes to business or production processes. | AK13: {=_xlfn.IFS(AC13="Principles observation",1, AC13="Concept formulation",2, AC13="Proof-of-concept simulation", 3, AC13="Core function validation", 4, AC13="Integration component testing", 5, AC13="Component validation in relevant environment", 6, AC13="Subsystem demonstration in relevant environment", 7, AC13="System demonstration in operational environment", 8, AC13="Production qualification", 9, AC13="Mission-proven operations", 10)} -> 4 | AL13: {=_xlfn.IFS(AD13="Assistive GenAI", 1, AD13="GenAI-led with human oversight", 2, AD13="Autonomous process learning", 3)} -> 1
A14: 14 | B14: Ontology-integrated tuning of large language model for intelligent maintenance | C14: Wang P.; Karigiannis J.; Gao R.X. | D14: 2024 | E14: CIRP Annals | F14: 8 | G14: =IFERROR(LEFT(C14, FIND(";", C14) - 1), C14) -> Wang P. | H14: Department of Electrical and Computer Engineering, Department of Mechanical and Aerospace Engineering, University of Kentucky, Lexington, KY, United States | I14: Large language models; Machine learning; Maintenance | J14: =IF(OR( E14="International Journal of Production Research", E14="Journal of Manufacturing Technology Management", E14="International Journal of Production Economics", E14="Journal of Industrial Information Integration", E14="Transportation Research Part E: Logistics and Transportation Review", E14="Journal of Cleaner Production", E14="MM 2024 - Proceedings of the 32nd ACM International Conference on Multimedia", E14="Oeconomia Copernicana", E14="Technology in Society" ), "MGT", "ENG") -> ENG | K14: empirical | L14: Design science research | M14: Techniques; Applications | N14: Operations | O14: maintenance | P14: Aerospace | R14: LLM chatbot | S14: ontologytuned gpt3.5 beats base gpt3.5/GP4 on component ID+action recs | T14: more accurate;consistent maint triage | U14: highqual ontology;curated logs | V14: fine tunning API limits;overfitting beyond 1 epoch;dataset repetition;generalizability | X14: encode aircraft ontology in logs;finetune gpt3.5;test on 500 logs;IoU/BERTScore/BLEU metrics | Y14: fine-tuned LLM on aircraft maintenance | Z14: 4 | AA14: 3 | AB14: Lab validation | AC14: Core function validation | AD14: Assistive GenAI | AE14: Y | AG14: GPT-3.5 is fine-tuned with curated aircraft maintenance logs and evaluated using IoU, BERTScore and BLEU, validating defect identification and action recommendation on historical data without integration to operational maintenance systems. | AH14: The fine-tuned LLM interprets free-text maintenance logs and suggests defective components and recommended actions, but humans remain responsible for decision-making and execution; the model neither triggers workflows nor controls equipment. | AI14: aircraft maintenance data is real | AK14: {=_xlfn.IFS(AC14="Principles observation",1, AC14="Concept formulation",2, AC14="Proof-of-concept simulation", 3, AC14="Core function validation", 4, AC14="Integration component testing", 5, AC14="Component validation in relevant environment", 6, AC14="Subsystem demonstration in relevant environment", 7, AC14="System demonstration in operational environment", 8, AC14="Production qualification", 9, AC14="Mission-proven operations", 10)} -> 4 | AL14: {=_xlfn.IFS(AD14="Assistive GenAI", 1, AD14="GenAI-led with human oversight", 2, AD14="Autonomous process learning", 3)} -> 1
A15: 15 | B15: Intelligent smelting process, management system: Efficient and intelligent management strategy by incorporating large language model | C15: Fu T.; Liu S.; Li P. | D15: 2024 | E15: Frontiers of Engineering Management | F15: 7 | G15: =IFERROR(LEFT(C15, FIND(";", C15) - 1), C15) -> Fu T. | H15: The School of Mechanical Engineering, Zhejiang University, Hangzhou, 310058, China | I15: ChatGPT; intelligent Q & A; large language models; process management; smelting steel | J15: =IF(OR( E15="International Journal of Production Research", E15="Journal of Manufacturing Technology Management", E15="International Journal of Production Economics", E15="Journal of Industrial Information Integration", E15="Transportation Research Part E: Logistics and Transportation Review", E15="Journal of Cleaner Production", E15="MM 2024 - Proceedings of the 32nd ACM International Conference on Multimedia", E15="Oeconomia Copernicana", E15="Technology in Society" ), "MGT", "ENG") -> ENG | K15: empirical | L15: Design science research | M15: Techniques; Applications | N15: Manufacturing | O15: anomaly detection | P15: steelmaking | R15: LLM chatbot; VLM | S15: fine tunw chatgpt3.5+clipbased vlm enable defect descrip+QA in smelting proc management | T15: lower management costs;higher eff;better proc comprehension;collaborative ops | U15: modle fine tunning | V15: integr gaps;data qual;need real deployments;reliance on chatgpt3.5 API | X15: chatgpt3.5 llm integrated w/fine tunw Transformer on domianspecific dataset+clipbased vlm | Y15: find tune LLM + VLM for anomaly detection | Z15: 4 | AA15: 3 | AB15: Field pilots | AC15: System demonstration in operational environment | AD15: Assistive GenAI | AE15: N | AF15: Field pilots – Subsystem demonstration in relevant environment | AG15: An integrated VLM+LLM management system connects to real smelting sensors, databases, and UI clients, and is evaluated in a steel plant with production and wastage improvements, indicating subsystem-level field demonstration | AH15: The ChatGPT-based module visualizes and explains smelting data, answers domain questions, and offers decision support. Human operators and managers still interpret advice, adjust parameters, and execute actions; GenAI never directly controls equipment or autonomously schedules production. | AI15: already tested it in a factory and have operational KPIs; and it's a complete system with full data flow, intergreted in a system | AK15: {=_xlfn.IFS(AC15="Principles observation",1, AC15="Concept formulation",2, AC15="Proof-of-concept simulation", 3, AC15="Core function validation", 4, AC15="Integration component testing", 5, AC15="Component validation in relevant environment", 6, AC15="Subsystem demonstration in relevant environment", 7, AC15="System demonstration in operational environment", 8, AC15="Production qualification", 9, AC15="Mission-proven operations", 10)} -> 8 | AL15: {=_xlfn.IFS(AD15="Assistive GenAI", 1, AD15="GenAI-led with human oversight", 2, AD15="Autonomous process learning", 3)} -> 1
A16: 16 | B16: ProcessCarbonAgent: A large language models-empowered autonomous agent for decision-making in manufacturing carbon emission management | C16: Wu T.; Li J.; Bao J.; Liu Q. | D16: 2024 | E16: Journal of Manufacturing Systems | F16: 7 | G16: =IFERROR(LEFT(C16, FIND(";", C16) - 1), C16) -> Wu T. | H16: College of Mechanical Engineering, Donghua University, Shanghai, 201620, China | I16: Assisted decision-making; Autonomous agents; Carbon emission management; Knowledge-intensive production; Large language models; Process carbon agent | J16: =IF(OR( E16="International Journal of Production Research", E16="Journal of Manufacturing Technology Management", E16="International Journal of Production Economics", E16="Journal of Industrial Information Integration", E16="Transportation Research Part E: Logistics and Transportation Review", E16="Journal of Cleaner Production", E16="MM 2024 - Proceedings of the 32nd ACM International Conference on Multimedia", E16="Oeconomia Copernicana", E16="Technology in Society" ), "MGT", "ENG") -> ENG | K16: empirical | L16: Design science research | M16: Techniques; Applications | N16: Manufacturing | O16: fault diagnosis; maintenance | P16: Textile | R16: LLM agents | S16: creates ProcessCarbonAgent:data/intention/CoT agents w/gpt4 controller;improve RCA acc/credibility+speeds carbonmanagement decisions | T16: technical suport for achieving lowcarbon transformation+intelligence in industrial prod processes | W16: Reason — Agents diagnose root causes by interpreting logs, retrieving similar cases, and debating evidence to recommendations. | X16: agent fw:combines data;intention+CoT agents w/gpt4 controller | Y16: agent framework; single-case textile validation | Z16: 4 | AA16: 4 | AB16: Lab validation | AC16: Core function validation | AD16: Assistive GenAI | AE16: Y | AG16: Offline study on historical carbon-emission logs from a textile plant, using semantic text and knowledge graphs, evaluated with automatic metrics and human scores, without deployment, real-time integration, or direct control of production equipment. | AH16: The agent analyzes process logs, retrieves similar cases, and generates textual root-cause explanations and improvement suggestions; engineers and managers interpret recommendations and decide process changes, so GenAI remains a decision-support copilot rather than executing actions. | AK16: {=_xlfn.IFS(AC16="Principles observation",1, AC16="Concept formulation",2, AC16="Proof-of-concept simulation", 3, AC16="Core function validation", 4, AC16="Integration component testing", 5, AC16="Component validation in relevant environment", 6, AC16="Subsystem demonstration in relevant environment", 7, AC16="System demonstration in operational environment", 8, AC16="Production qualification", 9, AC16="Mission-proven operations", 10)} -> 4 | AL16: {=_xlfn.IFS(AD16="Assistive GenAI", 1, AD16="GenAI-led with human oversight", 2, AD16="Autonomous process learning", 3)} -> 1
A17: 17 | B17: Do LLMs Understand Visual Anomalies? Uncovering LLM's Capabilities in Zero-shot Anomaly Detection | C17: Zhu J.; Cai S.; Deng F.; Ooi B.C.; Wu J. | D17: 2024 | E17: MM 2024 - Proceedings of the 32nd ACM International Conference on Multimedia | F17: 5 | G17: =IFERROR(LEFT(C17, FIND(";", C17) - 1), C17) -> Zhu J. | H17: Beijing Institute of Technology, Beijing, China | I17: industrial manufacturing; large vision-language model; visual anomaly detection; zero-shot detection | J17: ENG | K17: empirical | L17: Design science research | M17: Techniques | N17: Manufacturing | O17: anomaly detection | R17: LLM chatbot; VLM | S17: trainingfree ALFA use llmguided prompts+fine grain alignment to detect more defects+pinpoint them | T17: cuts manual prompt engineering;improve zeroshot inspection acc;better pixellevel localization | X17: alfa trainingfree;zeroshot visual anomaly detector combining gpt3.5generated prompts;CLIP visionlanguage features,+fine grain alignment module to score/pixellocalize defects on industrial images w/improved | Y17: training-free LLM + VLM for anomaly detection | Z17: 4 | AA17: 4 | AB17: Lab validation | AC17: Core function validation | AD17: Assistive GenAI | AE17: Y | AG17: Builds an LVLM+LLM pipeline for zero-shot visual anomaly detection and evaluates it on MVTec-AD, VisA and other benchmark datasets, entirely offline, with no integration to manufacturing equipment, sensors, or execution systems | AH17: The system outputs anomaly scores or maps for images; humans or downstream tooling would still decide inspection, repair, or adjustments. The paper targets detection performance, not autonomous closed-loop quality control, routing, or process actuation | AK17: {=_xlfn.IFS(AC17="Principles observation",1, AC17="Concept formulation",2, AC17="Proof-of-concept simulation", 3, AC17="Core function validation", 4, AC17="Integration component testing", 5, AC17="Component validation in relevant environment", 6, AC17="Subsystem demonstration in relevant environment", 7, AC17="System demonstration in operational environment", 8, AC17="Production qualification", 9, AC17="Mission-proven operations", 10)} -> 4 | AL17: {=_xlfn.IFS(AD17="Assistive GenAI", 1, AD17="GenAI-led with human oversight", 2, AD17="Autonomous process learning", 3)} -> 1
A18: 18 | B18: Interoperable information modelling leveraging asset administration shell and large language model for quality control toward zero defect manufacturing | C18: Shi D.; Liedl P.; Bauernhansl T. | D18: 2024 | E18: Journal of Manufacturing Systems | F18: 3 | G18: =IFERROR(LEFT(C18, FIND(";", C18) - 1), C18) -> Shi D. | H18: Fraunhofer Institute for Manufacturing Engineering and Automation IPA, Nobelstraße 12, Stuttgart, 70569, Germany | I18: Asset administration shell; Industry 4.0; Information modelling; Interoperability; Large language model; Ontology; Quality control; Zero defect manufacturing | J18: =IF(OR( E18="International Journal of Production Research", E18="Journal of Manufacturing Technology Management", E18="International Journal of Production Economics", E18="Journal of Industrial Information Integration", E18="Transportation Research Part E: Logistics and Transportation Review", E18="Journal of Cleaner Production", E18="MM 2024 - Proceedings of the 32nd ACM International Conference on Multimedia", E18="Oeconomia Copernicana", E18="Technology in Society" ), "MGT", "ENG") -> ENG | K18: empirical | L18: Design science research | M18: Techniques | N18: Operations | O18: quality management | R18: LLM enabled digital twin | S18: aas asset administration shell+llm automates semantic referencing;cuts manual effort,+improve data interoperability | T18: use of llmbased semantic search function to query information+data within AAS instance for qual | V18: data heterogeneity;fine tunning resorces demands;domian prompts required;singledomian vaild | W18: Align — Maps terms to standards and links datasets, grounding queries for interoperable, findable quality data access. | X18: an llmbased semantic search maps each AAS Submodel Template SMT property name+descrip to correct;An llmChat interface gpt41106preview w/Azure lets users ask NL questions over AAS instances hosted on | Y18: LLM acts as both a semantic mapper (to standards like ECLASS) and a natural-language interface over AAS data | Z18: 4 | AA18: 3 | AB18: Field pilots | AC18: Subsystem demonstration in relevant environment | AD18: Assistive GenAI | AE18: Y | AG18: Implements AAS templates, edge gateways, and LLM-based semantic search on quality data in a real injection-molding line, streaming production measurements into SMT instances and demonstrating subsystem behavior in the operational plant, without closing the control loop. | AH18: The LLM supports semantic search, schema alignment, and interactive querying over AAS instances, helping engineers and data scientists discover quality-relevant information; it neither proposes nor automatically executes process changes, remaining a knowledge and query assistant. | AK18: {=_xlfn.IFS(AC18="Principles observation",1, AC18="Concept formulation",2, AC18="Proof-of-concept simulation", 3, AC18="Core function validation", 4, AC18="Integration component testing", 5, AC18="Component validation in relevant environment", 6, AC18="Subsystem demonstration in relevant environment", 7, AC18="System demonstration in operational environment", 8, AC18="Production qualification", 9, AC18="Mission-proven operations", 10)} -> 7 | AL18: {=_xlfn.IFS(AD18="Assistive GenAI", 1, AD18="GenAI-led with human oversight", 2, AD18="Autonomous process learning", 3)} -> 1
A19: 19 | B19: Brain-like Cognition-Driven Model Factory for IIoT Fault Diagnosis by Combining LLMs With Small Models | C19: Liu Y.; Zhang W.; Bao Z.; Chai X.; Gu M.; Jiang W.; Zhang Z.; Tian Y.; Wang F.-Y. | D19: 2024 | E19: IEEE Internet of Things Journal | F19: 3 | G19: =IFERROR(LEFT(C19, FIND(";", C19) - 1), C19) -> Liu Y. | H19: China University of Petroleum (East China), College of Computer Science and Technology, Qingdao, 266580, China | I19: Brain-like cognition; fault diagnosis; generative vertical federated learning; LLMs; model factory; small models | J19: =IF(OR( E19="International Journal of Production Research", E19="Journal of Manufacturing Technology Management", E19="International Journal of Production Economics", E19="Journal of Industrial Information Integration", E19="Transportation Research Part E: Logistics and Transportation Review", E19="Journal of Cleaner Production", E19="MM 2024 - Proceedings of the 32nd ACM International Conference on Multimedia", E19="Oeconomia Copernicana", E19="Technology in Society" ), "MGT", "ENG") -> ENG | K19: empirical | L19: Design science research | M19: Techniques | N19: Operations | O19: maintenance | R19: LLM chatbot | S19: blcoT llm+GVFL small modles boost diagnostic acc/comprehension+communication eff across five datasets | T19: higher acc;better fault understanding;quicker maint advice | V19: llm domian gaps;heterogeneous features;tuning+privacy | X19: propose modle factory coupling BLCoTguided llm w/hypernetworkgenerated small modles under vertical federated learning;improving IIoT fault diag acc+maint guidance across five datasets | Y19: the LLM is the reasoning and coordination brain: 1. Knowledge-guided reasoning (BLCoT): The LLM is prompted with a brain-like chain-of-thought (BLCoT) template and a fault knowledge graph. 2. Supervisor of a “model factory”: The LLM acts as a supervisor that coordinates many small, specialized models (built via a hypernetwork) 3. Interactive maintenance assistant: The LLM explains the suspected fault in natural language, outlines why, and proposes next diagnostic checks or maintenance steps. | Z19: 4 | AA19: 3 | AB19: Lab validation | AC19: Core function validation | AD19: Assistive GenAI | AE19: Y | AG19: BC-MF is validated on four public IIoT datasets and one proprietary dataset, vertically partitioned for federated learning, with experiments restricted to offline training and evaluation rather than connection to running industrial assets or control systems. | AH19: The LLM supervises feature extraction and reasoning, then returns fault labels and maintenance recommendations, while small models perform precise diagnosis; technicians still decide and implement actions, so the framework augments analysis rather than autonomously operating equipment. | AK19: {=_xlfn.IFS(AC19="Principles observation",1, AC19="Concept formulation",2, AC19="Proof-of-concept simulation", 3, AC19="Core function validation", 4, AC19="Integration component testing", 5, AC19="Component validation in relevant environment", 6, AC19="Subsystem demonstration in relevant environment", 7, AC19="System demonstration in operational environment", 8, AC19="Production qualification", 9, AC19="Mission-proven operations", 10)} -> 4 | AL19: {=_xlfn.IFS(AD19="Assistive GenAI", 1, AD19="GenAI-led with human oversight", 2, AD19="Autonomous process learning", 3)} -> 1
A20: 21 | B20: Enhancing Quality Control: A Study on AI and Human Performance in Flip Chip Defect Detection | C20: Cheamsiri W.; Jitpattanakul A.; Muneesawang P.; Wongpatikaseree K.; Hnoohom N. | D20: 2024 | E20: IEEE Access | F20: 1 | G20: =IFERROR(LEFT(C20, FIND(";", C20) - 1), C20) -> Cheamsiri W. | H20: Faculty of Engineering, Mahidol University, Image Information and Intelligence Laboratory, Department of Computer Engineering, Nakhon Pathom, 73170, Thailand | I20: cross section; deep learning; Flip chip defect; generative artificial intelligence; object detection; YOLO models | J20: =IF(OR( E20="International Journal of Production Research", E20="Journal of Manufacturing Technology Management", E20="International Journal of Production Economics", E20="Journal of Industrial Information Integration", E20="Transportation Research Part E: Logistics and Transportation Review", E20="Journal of Cleaner Production", E20="MM 2024 - Proceedings of the 32nd ACM International Conference on Multimedia", E20="Oeconomia Copernicana", E20="Technology in Society" ), "MGT", "ENG") -> ENG | K20: empirical | L20: Design science research | M20: Techniques; Applications | N20: Manufacturing | O20: anomaly detection | P20: Semiconductor | R20: data augmentation | S20: generative augmentation improve minorityclass recall | T20: highmagnification imaging;classbalanced datasets | V20: hip scarcity | W20: Align — Generates scarce defect examples and balances classes to improve training recall and robustness during inspection | X20: getimg.ai gen synthetic HIP images from existing ones to enhance dataset+address HIP image imbalance | Y20: genAI for image data augmentation | Z20: 3 | AA20: 3 | AB20: Lab validation | AC20: Core function validation | AD20: Assistive GenAI | AE20: Y | AG20: Prototype defect-detection models trained with real microscope images from an EMS provider, augmented using generative AI. Evaluation is offline on curated datasets, with no integration into inline inspection equipment or factory IT systems. | AH20: Generative model only synthesizes images for training, while the defect detector provides classification results for inspectors or future systems; no autonomous process control, routing, or closed-loop adjustments are executed. | AK20: {=_xlfn.IFS(AC20="Principles observation",1, AC20="Concept formulation",2, AC20="Proof-of-concept simulation", 3, AC20="Core function validation", 4, AC20="Integration component testing", 5, AC20="Component validation in relevant environment", 6, AC20="Subsystem demonstration in relevant environment", 7, AC20="System demonstration in operational environment", 8, AC20="Production qualification", 9, AC20="Mission-proven operations", 10)} -> 4 | AL20: {=_xlfn.IFS(AD20="Assistive GenAI", 1, AD20="GenAI-led with human oversight", 2, AD20="Autonomous process learning", 3)} -> 1
A21: 22 | B21: Revolutionizing glass molding process: ChatGPT’s role in repairing and recycling lenses | C21: Cao S.; Lim W.H.; Zhu Y.J.; Li T.Y.; Liu Z.H.; Sheng H.Y. | D21: 2024 | E21: International Journal of Advanced Manufacturing Technology | F21: 0 | G21: =IFERROR(LEFT(C21, FIND(";", C21) - 1), C21) -> Cao S. | H21: Faculty of Engineering, Technology and Built Environment, UCSI University, Kuala Lumpur, 56000, Malaysia | I21: ChatGPT; CO<sub>2</sub> emissions; Energy consumption; Glass molding process; Recycling plans | J21: =IF(OR( E21="International Journal of Production Research", E21="Journal of Manufacturing Technology Management", E21="International Journal of Production Economics", E21="Journal of Industrial Information Integration", E21="Transportation Research Part E: Logistics and Transportation Review", E21="Journal of Cleaner Production", E21="MM 2024 - Proceedings of the 32nd ACM International Conference on Multimedia", E21="Oeconomia Copernicana", E21="Technology in Society" ), "MGT", "ENG") -> ENG | K21: empirical | L21: Design science research | M21: Applications | N21: Manufacturing | O21: re-manufacturing | R21: LLM chatbot | S21: chatgpt provides feasible plans for Repair/recycle substandard molded lenses | T21: faster option generation | V21: not always optimal;need vaild;impl complexity for some plans;domian expertise needed | X21: use chatgpt to propose+experimentally validate lens recycling plans | Y21: using ChatGPT to design recycling/repair plans for glass molding process lenses. ChatGPT proposes six recycling plans; lab experiments evaluate quality, economics, and green performance. | Z21: 4 | AA21: 2 | AB21: Lab validation | AC21: Core function validation | AD21: Assistive GenAI | AE21: Y | AG21: ChatGPT is used to propose modified repair and recycling process routes, then recipes are experimentally tested on lab-scale glass molding and annealing equipment with real lenses, showing technical feasibility but no production-line integration. | AH21: ChatGPT suggests process parameters, repair strategies, and troubleshooting ideas in natural language; human experts filter responses, design experiments, set machine parameters, and run trials, so GenAI informs decisions without directly executing or supervising manufacturing operations. | AK21: {=_xlfn.IFS(AC21="Principles observation",1, AC21="Concept formulation",2, AC21="Proof-of-concept simulation", 3, AC21="Core function validation", 4, AC21="Integration component testing", 5, AC21="Component validation in relevant environment", 6, AC21="Subsystem demonstration in relevant environment", 7, AC21="System demonstration in operational environment", 8, AC21="Production qualification", 9, AC21="Mission-proven operations", 10)} -> 4 | AL21: {=_xlfn.IFS(AD21="Assistive GenAI", 1, AD21="GenAI-led with human oversight", 2, AD21="Autonomous process learning", 3)} -> 1
A22: 23 | B22: SHIELD: LLM-Driven Schema Induction for Predictive Analytics in EV Battery Supply Chain Disruptions | C22: Cheng Z.-Q.; Dong Y.; Shi A.; Liu W.; Hu Y.; O’Connor J.; Hauptmann A.G.; Whitefoot K.S. | D22: 2024 | E22: EMNLP 2024 - 2024 Conference on Empirical Methods in Natural Language Processing, Proceedings of the Industry Track | F22: 0 | G22: =IFERROR(LEFT(C22, FIND(";", C22) - 1), C22) -> Cheng Z.-Q. | H22: Carnegie Mellon University, United States | J22: =IF(OR( E22="International Journal of Production Research", E22="Journal of Manufacturing Technology Management", E22="International Journal of Production Economics", E22="Journal of Industrial Information Integration", E22="Transportation Research Part E: Logistics and Transportation Review", E22="Journal of Cleaner Production", E22="MM 2024 - Proceedings of the 32nd ACM International Conference on Multimedia", E22="Oeconomia Copernicana", E22="Technology in Society" ), "MGT", "ENG") -> ENG | K22: empirical | L22: Design science research | M22: Applications | N22: Supply Chain | O22: disruption prediction | P22: automotive | R22: LLM chatbot | S22: llms gpt4o;Llama3 for schema;fine tunw roberta;GCNs w/logical constaints | X22: llms first draft disruption schemas;event+actor templates w/slots;reviewed by experts;Then they propose schema matches for each news paragraph | Y22: LLM-driven schema learning to construct a comprehensive knowledge library | Z22: 4 | AA22: 4 | AB22: Lab validation | AC22: Core function validation | AD22: Assistive GenAI | AE22: Y | AG22: SHIELD implements an LLM-based pipeline that induces schemas and features from EV battery disruption texts and evaluates predictive performance on historical corpora, but remains a research prototype without deployment into operational supply-chain planning systems. | AH22: The LLM structures data, generates features, and produces explanations that support analysts’ predictive models; humans interpret results and decide mitigation actions, so GenAI enhances analytics but does not autonomously trigger supply-chain interventions. | AK22: {=_xlfn.IFS(AC22="Principles observation",1, AC22="Concept formulation",2, AC22="Proof-of-concept simulation", 3, AC22="Core function validation", 4, AC22="Integration component testing", 5, AC22="Component validation in relevant environment", 6, AC22="Subsystem demonstration in relevant environment", 7, AC22="System demonstration in operational environment", 8, AC22="Production qualification", 9, AC22="Mission-proven operations", 10)} -> 4 | AL22: {=_xlfn.IFS(AD22="Assistive GenAI", 1, AD22="GenAI-led with human oversight", 2, AD22="Autonomous process learning", 3)} -> 1
